Workbook
Name Slicer_Weight_Status: #N/A

Sheet Customer Names
A1: Customer ID | B1: name | E1: Customer ID | F1: name | G1: Title | H1: First Name | I1: Last Name
A2: Id1 | B2: Hawks, Ms. Kelly | E2: Id1 | F2: Hawks, Ms. Kelly | G2: Ms | H2: Hawks | I2: Kelly
A3: Id2 | B3: Lehner, Mr. Matthew D | E3: Id2 | F3: Lehner, Mr. Matthew D | G3: Mr | H3: Lehner | I3: Matthew D | K3: 1 | L3: Checking the duplicate values in Customer ID.
A4: Id3 | B4: Lu, Mr. Phil | E4: Id3 | F4: Lu, Mr. Phil | G4: Mr | H4: Lu | I4: Phil | K4: 2 | L4: Use Trim in Name column.
A5: Id4 | B5: Osborne, Ms. Kelsey | E5: Id4 | F5: Osborne, Ms. Kelsey | G5: Ms | H5: Osborne | I5: Kelsey | K5: 3 | L5: Using Delimiter to spilt the Name
A6: Id5 | B6: Kadala, Ms. Kristyn | E6: Id5 | F6: Kadala, Ms. Kristyn | G6: Ms | H6: Kadala | I6: Kristyn
A7: Id6 | B7: Baker, Mr. Russell B. | E7: Id6 | F7: Baker, Mr. Russell B. | G7: Mr | H7: Baker | I7: Russell B
A8: Id7 | B8: Macpherson, Mr. Scott | E8: Id7 | F8: Macpherson, Mr. Scott | G8: Mr | H8: Macpherson | I8: Scott
A9: Id8 | B9: Hallman, Mr. Stephen | E9: Id8 | F9: Hallman, Mr. Stephen | G9: Mr | H9: Hallman | I9: Stephen
A10: Id9 | B10: Moran, Mr. Patrick R. | E10: Id9 | F10: Moran, Mr. Patrick R. | G10: Mr | H10: Moran | I10: Patrick R
A11: Id10 | B11: Benner, Ms. Brooke N. | E11: Id10 | F11: Benner, Ms. Brooke N. | G11: Ms | H11: Benner | I11: Brooke N
A12: Id11 | B12: Fierro Vargas, Ms. Paola Andrea | E12: Id11 | F12: Fierro Vargas, Ms. Paola Andrea | G12: Ms | H12: Fierro Vargas | I12: Paola Andrea
A13: Id12 | B13: Franz, Mr. David | E13: Id12 | F13: Franz, Mr. David | G13: Mr | H13: Franz | I13: David
A14: Id13 | B14: Foster, Mr. Wade | E14: Id13 | F14: Foster, Mr. Wade | G14: Mr | H14: Foster | I14: Wade
A15: Id14 | B15: Tenorio, Mr. Franklin | E15: Id14 | F15: Tenorio, Mr. Franklin | G15: Mr | H15: Tenorio | I15: Franklin
A16: Id15 | B16: Rios, Ms. Leilani M. | E16: Id15 | F16: Rios, Ms. Leilani M. | G16: Ms | H16: Rios | I16: Leilani M
A17: Id16 | B17: Viau-Dupuis, Mr. Philippe | E17: Id16 | F17: Viau-Dupuis, Mr. Philippe | G17: Mr | H17: Viau-Dupuis | I17: Philippe
... A2336: Id2335 | B2336: German, Mr. Aaron K | E2336: Id2335 | F2336: German, Mr. Aaron K | G2336: Mr | H2336: German | I2336: Aaron K

Sheet Medical Examinations
A1: Customer ID | B1: BMI | C1: HBA1C | D1: Heart Issues | E1: Any Transplants | F1: Cancer history | G1: NumberOfMajorSurgeries | H1: smoker | J1: Customer ID | K1: BMI | L1: HBA1C | M1: Heart Issues | N1: Any Transplants | O1: Cancer history | P1: NumberOfMajorSurgeries | Q1: smoker | R1: Encoding Smoker | S1: Weight Status
A2: Id1 | B2: 47.41 | C2: 7.47 | D2: No | E2: No | F2: No | G2: No major surgery | H2: yes | J2: Id1 | K2: 47.41 | L2: 7.47 | M2: No | N2: No | O2: No | P2: 0 | Q2: Yes | R2: =MATCH(Q2,$Q$2:$Q$2336,0) -> 1 | S2: {=_xlfn.IFS(K2<18.5,"Under Weight",K2<=24.9,"Normal Weight",K2<=30,"Over Weight",K2>30,"Obesity")} -> Obesity
A3: Id2 | B3: 30.36 | C3: 5.77 | D3: No | E3: No | F3: No | G3: No major surgery | H3: yes | J3: Id2 | K3: 30.36 | L3: 5.77 | M3: No | N3: No | O3: No | P3: 0 | Q3: Yes | R3: =MATCH(Q3,$Q$2:$Q$2336,0) -> 1 | S3: {=_xlfn.IFS(K3<18.5,"Under Weight",K3<=24.9,"Normal Weight",K3<=30,"Over Weight",K3>30,"Obesity")} -> Obesity | V3: 1 | W3: =MODE(R2:R2336) -> 180 | X3: Using Match for update missing value Smoke
A4: Id3 | B4: 34.485 | C4: 11.87 | D4: yes | E4: No | F4: No | G4: 2 | H4: yes | J4: Id3 | K4: 34.485 | L4: 11.87 | M4: Yes | N4: No | O4: No | P4: 2 | Q4: Yes | R4: =MATCH(Q4,$Q$2:$Q$2336,0) -> 1 | S4: {=_xlfn.IFS(K4<18.5,"Under Weight",K4<=24.9,"Normal Weight",K4<=30,"Over Weight",K4>30,"Obesity")} -> Obesity | V4: 2 | X4: Update 0 value for no major surgery using replace function
A5: Id4 | B5: 38.095 | C5: 6.05 | D5: No | E5: No | F5: No | G5: No major surgery | H5: yes | J5: Id4 | K5: 38.095 | L5: 6.05 | M5: No | N5: No | O5: No | P5: 0 | Q5: Yes | R5: =MATCH(Q5,$Q$2:$Q$2336,0) -> 1 | S5: {=_xlfn.IFS(K5<18.5,"Under Weight",K5<=24.9,"Normal Weight",K5<=30,"Over Weight",K5>30,"Obesity")} -> Obesity | V5: 3 | X5: Convert Heart issue and smoker column using "Proper"
A6: Id5 | B6: 35.53 | C6: 5.45 | D6: No | E6: No | F6: No | G6: No major surgery | H6: yes | J6: Id5 | K6: 35.53 | L6: 5.45 | M6: No | N6: No | O6: No | P6: 0 | Q6: Yes | R6: =MATCH(Q6,$Q$2:$Q$2336,0) -> 1 | S6: {=_xlfn.IFS(K6<18.5,"Under Weight",K6<=24.9,"Normal Weight",K6<=30,"Over Weight",K6>30,"Obesity")} -> Obesity | X6: Create Weight Status Column using Ifs function
A7: Id6 | B7: 32.8 | C7: 6.59 | D7: No | E7: No | F7: No | G7: No major surgery | H7: yes | J7: Id6 | K7: 32.8 | L7: 6.59 | M7: No | N7: No | O7: No | P7: 0 | Q7: Yes | R7: =MATCH(Q7,$Q$2:$Q$2336,0) -> 1 | S7: {=_xlfn.IFS(K7<18.5,"Under Weight",K7<=24.9,"Normal Weight",K7<=30,"Over Weight",K7>30,"Obesity")} -> Obesity
A8: Id7 | B8: 36.4 | C8: 6.07 | D8: No | E8: No | F8: No | G8: No major surgery | H8: yes | J8: Id7 | K8: 36.4 | L8: 6.07 | M8: No | N8: No | O8: No | P8: 0 | Q8: Yes | R8: =MATCH(Q8,$Q$2:$Q$2336,0) -> 1 | S8: {=_xlfn.IFS(K8<18.5,"Under Weight",K8<=24.9,"Normal Weight",K8<=30,"Over Weight",K8>30,"Obesity")} -> Obesity
A9: Id8 | B9: 36.96 | C9: 7.93 | D9: No | E9: No | F9: No | G9: 3 | H9: yes | J9: Id8 | K9: 36.96 | L9: 7.93 | M9: No | N9: No | O9: No | P9: 3 | Q9: Yes | R9: =MATCH(Q9,$Q$2:$Q$2336,0) -> 1 | S9: {=_xlfn.IFS(K9<18.5,"Under Weight",K9<=24.9,"Normal Weight",K9<=30,"Over Weight",K9>30,"Obesity")} -> Obesity
A10: Id9 | B10: 41.14 | C10: 9.58 | D10: yes | E10: No | F10: Yes | G10: 1 | H10: yes | J10: Id9 | K10: 41.14 | L10: 9.58 | M10: Yes | N10: No | O10: Yes | P10: 1 | Q10: Yes | R10: =MATCH(Q10,$Q$2:$Q$2336,0) -> 1 | S10: {=_xlfn.IFS(K10<18.5,"Under Weight",K10<=24.9,"Normal Weight",K10<=30,"Over Weight",K10>30,"Obesity")} -> Obesity
A11: Id10 | B11: 38.06 | C11: 10.79 | D11: No | E11: No | F11: No | G11: No major surgery | H11: yes | J11: Id10 | K11: 38.06 | L11: 10.79 | M11: No | N11: No | O11: No | P11: 0 | Q11: Yes | R11: =MATCH(Q11,$Q$2:$Q$2336,0) -> 1 | S11: {=_xlfn.IFS(K11<18.5,"Under Weight",K11<=24.9,"Normal Weight",K11<=30,"Over Weight",K11>30,"Obesity")} -> Obesity
A12: Id11 | B12: 37.7 | C12: 5.96 | D12: yes | E12: No | F12: No | G12: 2 | H12: yes | J12: Id11 | K12: 37.7 | L12: 5.96 | M12: Yes | N12: No | O12: No | P12: 2 | Q12: Yes | R12: =MATCH(Q12,$Q$2:$Q$2336,0) -> 1 | S12: {=_xlfn.IFS(K12<18.5,"Under Weight",K12<=24.9,"Normal Weight",K12<=30,"Over Weight",K12>30,"Obesity")} -> Obesity
A13: Id12 | B13: 42.13 | C13: 11.9 | D13: No | E13: No | F13: No | G13: No major surgery | H13: yes | J13: Id12 | K13: 42.13 | L13: 11.9 | M13: No | N13: No | O13: No | P13: 0 | Q13: Yes | R13: =MATCH(Q13,$Q$2:$Q$2336,0) -> 1 | S13: {=_xlfn.IFS(K13<18.5,"Under Weight",K13<=24.9,"Normal Weight",K13<=30,"Over Weight",K13>30,"Obesity")} -> Obesity
A14: Id13 | B14: 40.92 | C14: 8.41 | D14: No | E14: No | F14: No | G14: No major surgery | H14: yes | J14: Id13 | K14: 40.92 | L14: 8.41 | M14: No | N14: No | O14: No | P14: 0 | Q14: Yes | R14: =MATCH(Q14,$Q$2:$Q$2336,0) -> 1 | S14: {=_xlfn.IFS(K14<18.5,"Under Weight",K14<=24.9,"Normal Weight",K14<=30,"Over Weight",K14>30,"Obesity")} -> Obesity
A15: Id14 | B15: 40.565 | C15: 7.02 | D15: No | E15: No | F15: No | G15: No major surgery | H15: yes | J15: Id14 | K15: 40.565 | L15: 7.02 | M15: No | N15: No | O15: No | P15: 0 | Q15: Yes | R15: =MATCH(Q15,$Q$2:$Q$2336,0) -> 1 | S15: {=_xlfn.IFS(K15<18.5,"Under Weight",K15<=24.9,"Normal Weight",K15<=30,"Over Weight",K15>30,"Obesity")} -> Obesity
A16: Id15 | B16: 36.385 | C16: 7.59 | D16: yes | E16: No | F16: No | G16: 2 | H16: yes | J16: Id15 | K16: 36.385 | L16: 7.59 | M16: Yes | N16: No | O16: No | P16: 2 | Q16: Yes | R16: =MATCH(Q16,$Q$2:$Q$2336,0) -> 1 | S16: {=_xlfn.IFS(K16<18.5,"Under Weight",K16<=24.9,"Normal Weight",K16<=30,"Over Weight",K16>30,"Obesity")} -> Obesity
A17: Id16 | B17: 39.9 | C17: 11.32 | D17: No | E17: No | F17: No | G17: No major surgery | H17: yes | J17: Id16 | K17: 39.9 | L17: 11.32 | M17: No | N17: No | O17: No | P17: 0 | Q17: Yes | R17: =MATCH(Q17,$Q$2:$Q$2336,0) -> 1 | S17: {=_xlfn.IFS(K17<18.5,"Under Weight",K17<=24.9,"Normal Weight",K17<=30,"Over Weight",K17>30,"Obesity")} -> Obesity
A18: Id17 | B18: 33.8 | C18: 7.67 | D18: No | E18: No | F18: No | G18: 3 | H18: yes | J18: Id17 | K18: 33.8 | L18: 7.67 | M18: No | N18: No | O18: No | P18: 3 | Q18: Yes | R18: =MATCH(Q18,$Q$2:$Q$2336,0) -> 1 | S18: {=_xlfn.IFS(K18<18.5,"Under Weight",K18<=24.9,"Normal Weight",K18<=30,"Over Weight",K18>30,"Obesity")} -> Obesity
A19: Id18 | B19: 36.765 | C19: 7.29 | D19: yes | E19: No | F19: Yes | G19: 1 | H19: yes | J19: Id18 | K19: 36.765 | L19: 7.29 | M19: Yes | N19: No | O19: Yes | P19: 1 | Q19: Yes | R19: =MATCH(Q19,$Q$2:$Q$2336,0) -> 1 | S19: {=_xlfn.IFS(K19<18.5,"Under Weight",K19<=24.9,"Normal Weight",K19<=30,"Over Weight",K19>30,"Obesity")} -> Obesity
A20: Id19 | B20: 36.955 | C20: 4.72 | D20: yes | E20: No | F20: No | G20: 1 | H20: yes | J20: Id19 | K20: 36.955 | L20: 4.72 | M20: Yes | N20: No | O20: No | P20: 1 | Q20: Yes | R20: =MATCH(Q20,$Q$2:$Q$2336,0) -> 1 | S20: {=_xlfn.IFS(K20<18.5,"Under Weight",K20<=24.9,"Normal Weight",K20<=30,"Over Weight",K20>30,"Obesity")} -> Obesity
A21: Id20 | B21: 42.9 | C21: 11.41 | D21: No | E21: No | F21: No | G21: No major surgery | H21: yes | J21: Id20 | K21: 42.9 | L21: 11.41 | M21: No | N21: No | O21: No | P21: 0 | Q21: Yes | R21: =MATCH(Q21,$Q$2:$Q$2336,0) -> 1 | S21: {=_xlfn.IFS(K21<18.5,"Under Weight",K21<=24.9,"Normal Weight",K21<=30,"Over Weight",K21>30,"Obesity")} -> Obesity
A22: Id21 | B22: 36.3 | C22: 11.5 | D22: yes | E22: No | F22: No | G22: 2 | H22: yes | J22: Id21 | K22: 36.3 | L22: 11.5 | M22: Yes | N22: No | O22: No | P22: 2 | Q22: Yes | R22: =MATCH(Q22,$Q$2:$Q$2336,0) -> 1 | S22: {=_xlfn.IFS(K22<18.5,"Under Weight",K22<=24.9,"Normal Weight",K22<=30,"Over Weight",K22>30,"Obesity")} -> Obesity
A23: Id22 | B23: 32.2 | C23: 6.22 | D23: yes | E23: No | F23: No | G23: 2 | H23: yes | J23: Id22 | K23: 32.2 | L23: 6.22 | M23: Yes | N23: No | O23: No | P23: 2 | Q23: Yes | R23: =MATCH(Q23,$Q$2:$Q$2336,0) -> 1 | S23: {=_xlfn.IFS(K23<18.5,"Under Weight",K23<=24.9,"Normal Weight",K23<=30,"Over Weight",K23>30,"Obesity")} -> Obesity
A24: Id23 | B24: 31.3 | C24: 11.38 | D24: No | E24: No | F24: No | G24: 3 | H24: yes | J24: Id23 | K24: 31.3 | L24: 11.38 | M24: No | N24: No | O24: No | P24: 3 | Q24: Yes | R24: =MATCH(Q24,$Q$2:$Q$2336,0) -> 1 | S24: {=_xlfn.IFS(K24<18.5,"Under Weight",K24<=24.9,"Normal Weight",K24<=30,"Over Weight",K24>30,"Obesity")} -> Obesity
A25: Id24 | B25: 41.8 | C25: 7.89 | D25: yes | E25: No | F25: No | G25: 2 | H25: yes | J25: Id24 | K25: 41.8 | L25: 7.89 | M25: Yes | N25: No | O25: No | P25: 2 | Q25: Yes | R25: =MATCH(Q25,$Q$2:$Q$2336,0) -> 1 | S25: {=_xlfn.IFS(K25<18.5,"Under Weight",K25<=24.9,"Normal Weight",K25<=30,"Over Weight",K25>30,"Obesity")} -> Obesity
A26: Id25 | B26: 35.09 | C26: 4.38 | D26: yes | E26: No | F26: No | G26: 2 | H26: yes | J26: Id25 | K26: 35.09 | L26: 4.38 | M26: Yes | N26: No | O26: No | P26: 2 | Q26: Yes | R26: =MATCH(Q26,$Q$2:$Q$2336,0) -> 1 | S26: {=_xlfn.IFS(K26<18.5,"Under Weight",K26<=24.9,"Normal Weight",K26<=30,"Over Weight",K26>30,"Obesity")} -> Obesity
A27: Id26 | B27: 33.88 | C27: 7.01 | D27: No | E27: No | F27: No | G27: 3 | H27: yes | J27: Id26 | K27: 33.88 | L27: 7.01 | M27: No | N27: No | O27: No | P27: 3 | Q27: Yes | R27: =MATCH(Q27,$Q$2:$Q$2336,0) -> 1 | S27: {=_xlfn.IFS(K27<18.5,"Under Weight",K27<=24.9,"Normal Weight",K27<=30,"Over Weight",K27>30,"Obesity")} -> Obesity
A28: Id27 | B28: 30.875 | C28: 11.88 | D28: No | E28: No | F28: No | G28: No major surgery | H28: yes | J28: Id27 | K28: 30.875 | L28: 11.88 | M28: No | N28: No | O28: No | P28: 0 | Q28: Yes | R28: =MATCH(Q28,$Q$2:$Q$2336,0) -> 1 | S28: {=_xlfn.IFS(K28<18.5,"Under Weight",K28<=24.9,"Normal Weight",K28<=30,"Over Weight",K28>30,"Obesity")} -> Obesity
A29: Id28 | B29: 36.86 | C29: 5.19 | D29: yes | E29: No | F29: Yes | G29: 1 | H29: yes | J29: Id28 | K29: 36.86 | L29: 5.19 | M29: Yes | N29: No | O29: Yes | P29: 1 | Q29: Yes | R29: =MATCH(Q29,$Q$2:$Q$2336,0) -> 1 | S29: {=_xlfn.IFS(K29<18.5,"Under Weight",K29<=24.9,"Normal Weight",K29<=30,"Over Weight",K29>30,"Obesity")} -> Obesity
A30: Id29 | B30: 35.86 | C30: 6.74 | D30: yes | E30: No | F30: No | G30: 2 | H30: yes | J30: Id29 | K30: 35.86 | L30: 6.74 | M30: Yes | N30: No | O30: No | P30: 2 | Q30: Yes | R30: =MATCH(Q30,$Q$2:$Q$2336,0) -> 1 | S30: {=_xlfn.IFS(K30<18.5,"Under Weight",K30<=24.9,"Normal Weight",K30<=30,"Over Weight",K30>30,"Obesity")} -> Obesity
A31: Id30 | B31: 37.05 | C31: 8.44 | D31: No | E31: No | F31: No | G31: No major surgery | H31: yes | J31: Id30 | K31: 37.05 | L31: 8.44 | M31: No | N31: No | O31: No | P31: 0 | Q31: Yes | R31: =MATCH(Q31,$Q$2:$Q$2336,0) -> 1 | S31: {=_xlfn.IFS(K31<18.5,"Under Weight",K31<=24.9,"Normal Weight",K31<=30,"Over Weight",K31>30,"Obesity")} -> Obesity
A32: Id31 | B32: 43.89 | C32: 8.71 | D32: No | E32: No | F32: No | G32: No major surgery | H32: yes | J32: Id31 | K32: 43.89 | L32: 8.71 | M32: No | N32: No | O32: No | P32: 0 | Q32: Yes | R32: =MATCH(Q32,$Q$2:$Q$2336,0) -> 1 | S32: {=_xlfn.IFS(K32<18.5,"Under Weight",K32<=24.9,"Normal Weight",K32<=30,"Over Weight",K32>30,"Obesity")} -> Obesity
A33: Id32 | B33: 42.35 | C33: 5.08 | D33: yes | E33: No | F33: No | G33: No major surgery | H33: yes | J33: Id32 | K33: 42.35 | L33: 5.08 | M33: Yes | N33: No | O33: No | P33: 0 | Q33: Yes | R33: =MATCH(Q33,$Q$2:$Q$2336,0) -> 1 | S33: {=_xlfn.IFS(K33<18.5,"Under Weight",K33<=24.9,"Normal Weight",K33<=30,"Over Weight",K33>30,"Obesity")} -> Obesity
A34: Id33 | B34: 31.35 | C34: 6.86 | D34: No | E34: No | F34: No | G34: No major surgery | H34: yes | J34: Id33 | K34: 31.35 | L34: 6.86 | M34: No | N34: No | O34: No | P34: 0 | Q34: Yes | R34: =MATCH(Q34,$Q$2:$Q$2336,0) -> 1 | S34: {=_xlfn.IFS(K34<18.5,"Under Weight",K34<=24.9,"Normal Weight",K34<=30,"Over Weight",K34>30,"Obesity")} -> Obesity
A35: Id34 | B35: 47.6 | C35: 5.95 | D35: yes | E35: No | F35: No | G35: No major surgery | H35: yes | J35: Id34 | K35: 47.6 | L35: 5.95 | M35: Yes | N35: No | O35: No | P35: 0 | Q35: Yes | R35: =MATCH(Q35,$Q$2:$Q$2336,0) -> 1 | S35: {=_xlfn.IFS(K35<18.5,"Under Weight",K35<=24.9,"Normal Weight",K35<=30,"Over Weight",K35>30,"Obesity")} -> Obesity
A36: Id35 | B36: 46.2 | C36: 6.09 | D36: No | E36: No | F36: Yes | G36: 1 | H36: yes | J36: Id35 | K36: 46.2 | L36: 6.09 | M36: No | N36: No | O36: Yes | P36: 1 | Q36: Yes | R36: =MATCH(Q36,$Q$2:$Q$2336,0) -> 1 | S36: {=_xlfn.IFS(K36<18.5,"Under Weight",K36<=24.9,"Normal Weight",K36<=30,"Over Weight",K36>30,"Obesity")} -> Obesity
A37: Id36 | B37: 32.015 | C37: 11.75 | D37: No | E37: No | F37: No | G37: No major surgery | H37: yes | J37: Id36 | K37: 32.015 | L37: 11.75 | M37: No | N37: No | O37: No | P37: 0 | Q37: Yes | R37: =MATCH(Q37,$Q$2:$Q$2336,0) -> 1 | S37: {=_xlfn.IFS(K37<18.5,"Under Weight",K37<=24.9,"Normal Weight",K37<=30,"Over Weight",K37>30,"Obesity")} -> Obesity
A38: Id37 | B38: 40.565 | C38: 7.37 | D38: No | E38: No | F38: No | G38: No major surgery | H38: yes | J38: Id37 | K38: 40.565 | L38: 7.37 | M38: No | N38: No | O38: No | P38: 0 | Q38: Yes | R38: =MATCH(Q38,$Q$2:$Q$2336,0) -> 1 | S38: {=_xlfn.IFS(K38<18.5,"Under Weight",K38<=24.9,"Normal Weight",K38<=30,"Over Weight",K38>30,"Obesity")} -> Obesity
A39: Id38 | B39: 32.45 | C39: 11.91 | D39: No | E39: No | F39: No | G39: No major surgery | H39: yes | J39: Id38 | K39: 32.45 | L39: 11.91 | M39: No | N39: No | O39: No | P39: 0 | Q39: Yes | R39: =MATCH(Q39,$Q$2:$Q$2336,0) -> 1 | S39: {=_xlfn.IFS(K39<18.5,"Under Weight",K39<=24.9,"Normal Weight",K39<=30,"Over Weight",K39>30,"Obesity")} -> Obesity
A40: Id39 | B40: 34.96 | C40: 6.52 | D40: No | E40: No | F40: No | G40: No major surgery | H40: yes | J40: Id39 | K40: 34.96 | L40: 6.52 | M40: No | N40: No | O40: No | P40: 0 | Q40: Yes | R40: =MATCH(Q40,$Q$2:$Q$2336,0) -> 1 | S40: {=_xlfn.IFS(K40<18.5,"Under Weight",K40<=24.9,"Normal Weight",K40<=30,"Over Weight",K40>30,"Obesity")} -> Obesity
...

Sheet Hospitalisation Details
A1: Customer ID | B1: year | C1: month | D1: date | E1: children | F1: charges | G1: Hospital tier | H1: City tier | I1: State ID | K1: Customer ID | L1: year | M1: month | N1: date | O1: children | P1: charges | Q1: Hospital tier | R1: City tier | S1: State ID | T1: Encloding_Hospital | U1: Encloding_Citi Tier | V1: Date of Birth’ | W1: For Age | X1: Age
A2: Id2335 | B2: 1992 | C2: Jul | D2: 9 | E2: 0 | F2: 563.84 | G2: tier - 2 | H2: tier - 3 | I2: R1013 | K2: Id2335 | L2: 1992 | M2: Jul | N2: 9 | O2: 0 | P2: 563.84 | Q2: tier - 2 | R2: tier - 3 | S2: R1013 | T2: =MATCH(Q2,$Q$2:$Q$2344,0) -> 1 | U2: =MATCH(R2,$R$2:$R$2344,0) -> 1 | V2: 9-Jul-1992 | W2: 45085 | X2: 30
A3: Id2334 | B3: 1992 | C3: Nov | D3: 30 | E3: 0 | F3: 570.62 | G3: tier - 2 | H3: tier - 1 | I3: R1013 | K3: Id2334 | L3: 1992 | M3: Nov | N3: 30 | O3: 0 | P3: 570.62 | Q3: tier - 2 | R3: tier - 1 | S3: R1013 | T3: =MATCH(Q3,$Q$2:$Q$2344,0) -> 1 | U3: =MATCH(R3,$R$2:$R$2344,0) -> 2 | V3: 30-Nov-1992 | W3: 45085 | X3: 30 | Y3: 1 | Z3: =AVERAGE(B2:B2344) -> 1982.8417 | AA3: =ROUND(Z3,0) -> 1983 | AB3: Using average for update missing year column
A4: Id2333 | B4: 1993 | C4: Jun | D4: 30 | E4: 0 | F4: 600 | G4: tier - 2 | H4: tier - 1 | I4: R1013 | K4: Id2333 | L4: 1993 | M4: Jun | N4: 30 | O4: 0 | P4: 600 | Q4: tier - 2 | R4: tier - 1 | S4: R1013 | T4: =MATCH(Q4,$Q$2:$Q$2344,0) -> 1 | U4: =MATCH(R4,$R$2:$R$2344,0) -> 2 | V4: 30-Jun-1993 | W4: 45085 | X4: 29 | Y4: 2 | AB4: Updated Sep in missing of month Column
A5: Id2332 | B5: 1992 | C5: Sep | D5: 13 | E5: 0 | F5: 604.54 | G5: tier - 3 | H5: tier - 3 | I5: R1013 | K5: Id2332 | L5: 1992 | M5: Sep | N5: 13 | O5: 0 | P5: 604.54 | Q5: tier - 3 | R5: tier - 3 | S5: R1013 | T5: =MATCH(Q5,$Q$2:$Q$2344,0) -> 4 | U5: =MATCH(R5,$R$2:$R$2344,0) -> 1 | V5: 13-Sep-1992 | W5: 45085 | X5: 30 | Y5: 3 | Z5: =MODE(T2:T2344) -> 1 | AA5: tier - 2 | AB5: Using Match for update missing value Hospital tier
A6: Id2331 | B6: 1998 | C6: Jul | D6: 27 | E6: 0 | F6: 637.26 | G6: tier - 3 | H6: tier - 3 | I6: R1013 | K6: Id2331 | L6: 1998 | M6: Jul | N6: 27 | O6: 0 | P6: 637.26 | Q6: tier - 3 | R6: tier - 3 | S6: R1013 | T6: =MATCH(Q6,$Q$2:$Q$2344,0) -> 4 | U6: =MATCH(R6,$R$2:$R$2344,0) -> 1 | V6: 27-Jul-1998 | W6: 45085 | X6: 24 | Y6: 4 | Z6: =MODE(U2:U2344) -> 9 | AA6: tier - 2 | AB6: Using Match for update missing value Citi tier
A7: Id2330 | B7: 2001 | C7: Nov | D7: 20 | E7: 0 | F7: 646.14 | G7: tier - 3 | H7: tier - 3 | I7: R1012 | K7: Id2330 | L7: 2001 | M7: Nov | N7: 20 | O7: 0 | P7: 646.14 | Q7: tier - 3 | R7: tier - 3 | S7: R1012 | T7: =MATCH(Q7,$Q$2:$Q$2344,0) -> 4 | U7: =MATCH(R7,$R$2:$R$2344,0) -> 1 | V7: 20-Nov-2001 | W7: 45085 | X7: 21 | Y7: 5 | AB7: Update Unknown for missing State ID
A8: Id2329 | B8: 1993 | C8: Jun | D8: 1 | E8: 0 | F8: 650 | G8: tier - 3 | H8: tier - 3 | I8: R1013 | K8: Id2329 | L8: 1993 | M8: Jun | N8: 1 | O8: 0 | P8: 650 | Q8: tier - 3 | R8: tier - 3 | S8: R1013 | T8: =MATCH(Q8,$Q$2:$Q$2344,0) -> 4 | U8: =MATCH(R8,$R$2:$R$2344,0) -> 1 | V8: 1-Jun-1993 | W8: 45085 | X8: 30 | AB8: Date of Birth - created using concatenate
A9: Id2328 | B9: 1995 | C9: Jul | D9: 4 | E9: 0 | F9: 650 | G9: tier - 3 | H9: tier - 3 | I9: R1013 | K9: Id2328 | L9: 1995 | M9: Jul | N9: 4 | O9: 0 | P9: 650 | Q9: tier - 3 | R9: tier - 3 | S9: R1013 | T9: =MATCH(Q9,$Q$2:$Q$2344,0) -> 4 | U9: =MATCH(R9,$R$2:$R$2344,0) -> 1 | V9: 4-Jul-1995 | W9: 45085 | X9: 27 | AB9: Age Calculated using Dateif()
A10: Id2327 | B10: 2002 | C10: Nov | D10: 29 | E10: 0 | F10: 668 | G10: tier - 3 | H10: tier - 2 | I10: R1012 | K10: Id2327 | L10: 2002 | M10: Nov | N10: 29 | O10: 0 | P10: 668 | Q10: tier - 3 | R10: tier - 2 | S10: R1012 | T10: =MATCH(Q10,$Q$2:$Q$2344,0) -> 4 | U10: =MATCH(R10,$R$2:$R$2344,0) -> 9 | V10: 29-Nov-2002 | W10: 45085 | X10: 20 | AB10: Convert currency in $
A11: Id2326 | B11: 1997 | C11: Nov | D11: 9 | E11: 0 | F11: 670 | G11: tier - 3 | H11: tier - 3 | I11: R1013 | K11: Id2326 | L11: 1997 | M11: Nov | N11: 9 | O11: 0 | P11: 670 | Q11: tier - 3 | R11: tier - 3 | S11: R1013 | T11: =MATCH(Q11,$Q$2:$Q$2344,0) -> 4 | U11: =MATCH(R11,$R$2:$R$2344,0) -> 1 | V11: 9-Nov-1997 | W11: 45085 | X11: 25
A12: Id2325 | B12: 2001 | C12: Sep | D12: 12 | E12: 0 | F12: 687.54 | G12: tier - 3 | H12: tier - 2 | I12: R1013 | K12: Id2325 | L12: 2001 | M12: Sep | N12: 12 | O12: 0 | P12: 687.54 | Q12: tier - 3 | R12: tier - 2 | S12: R1013 | T12: =MATCH(Q12,$Q$2:$Q$2344,0) -> 4 | U12: =MATCH(R12,$R$2:$R$2344,0) -> 9 | V12: 12-Sep-2001 | W12: 45085 | X12: 21
A13: Id2324 | B13: 1999 | C13: Dec | D13: 26 | E13: 0 | F13: 700 | G13: ? | H13: tier - 3 | I13: R1013 | K13: Id2324 | L13: 1999 | M13: Dec | N13: 26 | O13: 0 | P13: 700 | Q13: tier - 2 | R13: tier - 3 | S13: R1013 | T13: =MATCH(Q13,$Q$2:$Q$2344,0) -> 1 | U13: =MATCH(R13,$R$2:$R$2344,0) -> 1 | V13: 26-Dec-1999 | W13: 45085 | X13: 23
A14: Id2323 | B14: 1999 | C14: Dec | D14: 14 | E14: 0 | F14: 722.99 | G14: tier - 3 | H14: tier - 1 | I14: R1013 | K14: Id2323 | L14: 1999 | M14: Dec | N14: 14 | O14: 0 | P14: 722.99 | Q14: tier - 3 | R14: tier - 1 | S14: R1013 | T14: =MATCH(Q14,$Q$2:$Q$2344,0) -> 4 | U14: =MATCH(R14,$R$2:$R$2344,0) -> 2 | V14: 14-Dec-1999 | W14: 45085 | X14: 23
A15: Id2322 | B15: 2002 | C15: Sep | D15: 19 | E15: 0 | F15: 750 | G15: tier - 3 | H15: tier - 1 | I15: R1012 | K15: Id2322 | L15: 2002 | M15: Sep | N15: 19 | O15: 0 | P15: 750 | Q15: tier - 3 | R15: tier - 1 | S15: R1012 | T15: =MATCH(Q15,$Q$2:$Q$2344,0) -> 4 | U15: =MATCH(R15,$R$2:$R$2344,0) -> 2 | V15: 19-Sep-2002 | W15: 45085 | X15: 20
A16: Id2321 | B16: 1993 | C16: Aug | D16: 9 | E16: 0 | F16: 760 | G16: tier - 3 | H16: tier - 1 | I16: R1013 | K16: Id2321 | L16: 1993 | M16: Aug | N16: 9 | O16: 0 | P16: 760 | Q16: tier - 3 | R16: tier - 1 | S16: R1013 | T16: =MATCH(Q16,$Q$2:$Q$2344,0) -> 4 | U16: =MATCH(R16,$R$2:$R$2344,0) -> 2 | V16: 9-Aug-1993 | W16: 45085 | X16: 29
A17: Id2320 | B17: 1996 | C17: Oct | D17: 22 | E17: 0 | F17: 760 | G17: tier - 3 | H17: tier - 3 | I17: R1013 | K17: Id2320 | L17: 1996 | M17: Oct | N17: 22 | O17: 0 | P17: 760 | Q17: tier - 3 | R17: tier - 3 | S17: R1013 | T17: =MATCH(Q17,$Q$2:$Q$2344,0) -> 4 | U17: =MATCH(R17,$R$2:$R$2344,0) -> 1 | V17: 22-Oct-1996 | W17: 45085 | X17: 26
A18: Id2319 | B18: 1993 | C18: Jun | D18: 28 | E18: 0 | F18: 770 | G18: tier - 3 | H18: tier - 3 | I18: R1013 | K18: Id2319 | L18: 1993 | M18: Jun | N18: 28 | O18: 0 | P18: 770 | Q18: tier - 3 | R18: tier - 3 | S18: R1013 | T18: =MATCH(Q18,$Q$2:$Q$2344,0) -> 4 | U18: =MATCH(R18,$R$2:$R$2344,0) -> 1 | V18: 28-Jun-1993 | W18: 45085 | X18: 29
A19: Id2318 | B19: 1996 | C19: Sep | D19: 18 | E19: 0 | F19: 770.38 | G19: tier - 3 | H19: ? | I19: R1012 | K19: Id2318 | L19: 1996 | M19: Sep | N19: 18 | O19: 0 | P19: 770.38 | Q19: tier - 3 | R19: tier - 2 | S19: R1012 | T19: =MATCH(Q19,$Q$2:$Q$2344,0) -> 4 | U19: =MATCH(R19,$R$2:$R$2344,0) -> 9 | V19: 18-Sep-1996 | W19: 45085 | X19: 26
A20: Id2317 | B20: 1995 | C20: Dec | D20: 7 | E20: 0 | F20: 773.54 | G20: tier - 3 | H20: tier - 2 | I20: R1013 | K20: Id2317 | L20: 1995 | M20: Dec | N20: 7 | O20: 0 | P20: 773.54 | Q20: tier - 3 | R20: tier - 2 | S20: R1013 | T20: =MATCH(Q20,$Q$2:$Q$2344,0) -> 4 | U20: =MATCH(R20,$R$2:$R$2344,0) -> 9 | V20: 7-Dec-1995 | W20: 45085 | X20: 27
A21: Id2316 | B21: 2004 | C21: Oct | D21: 7 | E21: 0 | F21: 830.52 | G21: tier - 3 | H21: tier - 2 | I21: R1011 | K21: Id2316 | L21: 2004 | M21: Oct | N21: 7 | O21: 0 | P21: 830.52 | Q21: tier - 3 | R21: tier - 2 | S21: R1011 | T21: =MATCH(Q21,$Q$2:$Q$2344,0) -> 4 | U21: =MATCH(R21,$R$2:$R$2344,0) -> 9 | V21: 7-Oct-2004 | W21: 45085 | X21: 18
A22: Id2315 | B22: 2000 | C22: Nov | D22: 18 | E22: 0 | F22: 865.41 | G22: tier - 3 | H22: tier - 1 | I22: R1013 | K22: Id2315 | L22: 2000 | M22: Nov | N22: 18 | O22: 0 | P22: 865.41 | Q22: tier - 3 | R22: tier - 1 | S22: R1013 | T22: =MATCH(Q22,$Q$2:$Q$2344,0) -> 4 | U22: =MATCH(R22,$R$2:$R$2344,0) -> 2 | V22: 18-Nov-2000 | W22: 45085 | X22: 22
... A30: Id2307 | B30: 1995 | C30: Oct | D30: 5 | E30: 0 | F30: 1033.74 | G30: tier - 3 | H30: tier - 1 | I30: R1013 | K30: Id2307 | L30: 1995 | M30: Oct | N30: 5 | O30: 0 | P30: 1033.74 | Q30: tier - 3 | R30: tier - 1 | S30: R1013 | T30: =MATCH(Q30,$Q$2:$Q$2344,0) -> 4 | U30: =MATCH(R30,$R$2:$R$2344,0) -> 2 | V30: 5-Oct-1995 | W30: 45085 | X30: 27
A31: Id2306 | B31: 1994 | C31: Nov | D31: 17 | E31: 0 | F31: 1044 | G31: tier - 3 | H31: tier - 2 | I31: R1013 | K31: Id2306 | L31: 1994 | M31: Nov | N31: 17 | O31: 0 | P31: 1044 | Q31: tier - 3 | R31: tier - 2 | S31: R1013 | T31: =MATCH(Q31,$Q$2:$Q$2344,0) -> 4 | U31: =MATCH(R31,$R$2:$R$2344,0) -> 9 | V31: 17-Nov-1994 | W31: 45085 | X31: 28 | Z31: `
A32: Id2305 | B32: 2002 | C32: Jul | D32: 20 | E32: 0 | F32: 1047 | G32: tier - 3 | H32: tier - 1 | I32: R1013 | K32: Id2305 | L32: 2002 | M32: Jul | N32: 20 | O32: 0 | P32: 1047 | Q32: tier - 3 | R32: tier - 1 | S32: R1013 | T32: =MATCH(Q32,$Q$2:$Q$2344,0) -> 4 | U32: =MATCH(R32,$R$2:$R$2344,0) -> 2 | V32: 20-Jul-2002 | W32: 45085 | X32: 20
A33: Id2304 | B33: 2002 | C33: Jul | D33: 1 | E33: 0 | F33: 1049 | G33: tier - 3 | H33: tier - 2 | I33: R1012 | K33: Id2304 | L33: 2002 | M33: Jul | N33: 1 | O33: 0 | P33: 1049 | Q33: tier - 3 | R33: tier - 2 | S33: R1012 | T33: =MATCH(Q33,$Q$2:$Q$2344,0) -> 4 | U33: =MATCH(R33,$R$2:$R$2344,0) -> 9 | V33: 1-Jul-2002 | W33: 45085 | X33: 20
A34: Id2303 | B34: 1995 | C34: Jun | D34: 1 | E34: 0 | F34: 1056 | G34: tier - 3 | H34: tier - 2 | I34: R1013 | K34: Id2303 | L34: 1995 | M34: Jun | N34: 1 | O34: 0 | P34: 1056 | Q34: tier - 3 | R34: tier - 2 | S34: R1013 | T34: =MATCH(Q34,$Q$2:$Q$2344,0) -> 4 | U34: =MATCH(R34,$R$2:$R$2344,0) -> 9 | V34: 1-Jun-1995 | W34: 45085 | X34: 28
A35: Id2302 | B35: 1993 | C35: Sep | D35: 28 | E35: 0 | F35: 1068 | G35: tier - 3 | H35: tier - 1 | I35: R1013 | K35: Id2302 | L35: 1993 | M35: Sep | N35: 28 | O35: 0 | P35: 1068 | Q35: tier - 3 | R35: tier - 1 | S35: R1013 | T35: =MATCH(Q35,$Q$2:$Q$2344,0) -> 4 | U35: =MATCH(R35,$R$2:$R$2344,0) -> 2 | V35: 28-Sep-1993 | W35: 45085 | X35: 29
A36: Id2301 | B36: 2004 | C36: Aug | D36: 24 | E36: 0 | F36: 1070 | G36: tier - 3 | H36: tier - 3 | I36: R1013 | K36: Id2301 | L36: 2004 | M36: Aug | N36: 24 | O36: 0 | P36: 1070 | Q36: tier - 3 | R36: tier - 3 | S36: R1013 | T36: =MATCH(Q36,$Q$2:$Q$2344,0) -> 4 | U36: =MATCH(R36,$R$2:$R$2344,0) -> 1 | V36: 24-Aug-2004 | W36: 45085 | X36: 18
A37: Id2300 | B37: 1997 | C37: Aug | D37: 13 | E37: 0 | F37: 1071 | G37: tier - 3 | H37: tier - 3 | I37: R1013 | K37: Id2300 | L37: 1997 | M37: Aug | N37: 13 | O37: 0 | P37: 1071 | Q37: tier - 3 | R37: tier - 3 | S37: R1013 | T37: =MATCH(Q37,$Q$2:$Q$2344,0) -> 4 | U37: =MATCH(R37,$R$2:$R$2344,0) -> 1 | V37: 13-Aug-1997 | W37: 45085 | X37: 25
A38: Id2299 | B38: 1998 | C38: Dec | D38: 26 | E38: 0 | F38: 1082 | G38: tier - 3 | H38: tier - 2 | I38: R1013 | K38: Id2299 | L38: 1998 | M38: Dec | N38: 26 | O38: 0 | P38: 1082 | Q38: tier - 3 | R38: tier - 2 | S38: R1013 | T38: =MATCH(Q38,$Q$2:$Q$2344,0) -> 4 | U38: =MATCH(R38,$R$2:$R$2344,0) -> 9 | V38: 26-Dec-1998 | W38: 45085 | X38: 24
A39: Id2298 | B39: 2002 | C39: Aug | D39: 13 | E39: 0 | F39: 1086 | G39: tier - 3 | H39: tier - 3 | I39: R1013 | K39: Id2298 | L39: 2002 | M39: Aug | N39: 13 | O39: 0 | P39: 1086 | Q39: tier - 3 | R39: tier - 3 | S39: R1013 | T39: =MATCH(Q39,$Q$2:$Q$2344,0) -> 4 | U39: =MATCH(R39,$R$2:$R$2344,0) -> 1 | V39: 13-Aug-2002 | W39: 45085 | X39: 20
A40: Id2297 | B40: 2004 | C40: Nov | D40: 12 | E40: 0 | F40: 1121.87 | G40: tier - 3 | H40: tier - 1 | I40: R1013 | K40: Id2297 | L40: 2004 | M40: Nov | N40: 12 | O40: 0 | P40: 1121.87 | Q40: tier - 3 | R40: tier - 1 | S40: R1013 | T40: =MATCH(Q40,$Q$2:$Q$2344,0) -> 4 | U40: =MATCH(R40,$R$2:$R$2344,0) -> 2 | V40: 12-Nov-2004 | W40: 45085 | X40: 18
A41: Id2296 | B41: 2004 | C41: Jun | D41: 14 | E41: 0 | F41: 1131.51 | G41: tier - 3 | H41: tier - 1 | I41: R1013 | K41: Id2296 | L41: 2004 | M41: Jun | N41: 14 | O41: 0 | P41: 1131.51 | Q41: tier - 3 | R41: tier - 1 | S41: R1013 | T41: =MATCH(Q41,$Q$2:$Q$2344,0) -> 4 | U41: =MATCH(R41,$R$2:$R$2344,0) -> 2 | V41: 14-Jun-2004 | W41: 45085 | X41: 18
A42: Id2295 | B42: 2002 | C42: Jul | D42: 19 | E42: 0 | F42: 1132 | G42: tier - 3 | H42: tier - 1 | I42: R1013 | K42: Id2295 | L42: 2002 | M42: Jul | N42: 19 | O42: 0 | P42: 1132 | Q42: tier - 3 | R42: tier - 1 | S42: R1013 | T42: =MATCH(Q42,$Q$2:$Q$2344,0) -> 4 | U42: =MATCH(R42,$R$2:$R$2344,0) -> 2 | V42: 19-Jul-2002 | W42: 45085 | X42: 20
A43: Id2294 | B43: 2004 | C43: Oct | D43: 6 | E43: 0 | F43: 1135 | G43: tier - 3 | H43: tier - 3 | I43: R1013 | K43: Id2294 | L43: 2004 | M43: Oct | N43: 6 | O43: 0 | P43: 1135 | Q43: tier - 3 | R43: tier - 3 | S43: R1013 | T43: =MATCH(Q43,$Q$2:$Q$2344,0) -> 4 | U43: =MATCH(R43,$R$2:$R$2344,0) -> 1 | V43: 6-Oct-2004 | W43: 45085 | X43: 18
... A2344: Id1 | B2344: 1968 | C2344: Oct | D2344: 12 | E2344: 0 | F2344: 63770.43 | G2344: tier - 1 | H2344: tier - 3 | I2344: R1013 | K2344: Id1 | L2344: 1968 | M2344: Oct | N2344: 12 | O2344: 0 | P2344: 63770.43 | Q2344: tier - 1 | R2344: tier - 3 | S2344: R1013 | T2344: =MATCH(Q2344,$Q$2:$Q$2344,0) -> 240 | U2344: =MATCH(R2344,$R$2:$R$2344,0) -> 1 | V2344: 12-Oct-1968 | W2344: 45085 | X2344: 54
T2346: =MODE(T1:T2344) -> 1

Sheet Pivot Table
A3: Row Labels | B3: Count of smoker
A4: No | B4: 1944
A5: Yes | B5: 391
A6: Grand Total | B6: 2335
A13: Row Labels | B13: Sum of charges
A14: Normal Weight | B14: 4242122
A15: Obesity | B15: 20307101
A16: Over Weight | B16: 5828855.8
A17: Under Weight | B17: 1214279.9
A18: Grand Total | B18: 31592359

Sheet Dash Board
A1: CANCER HISTORY DISTRIBUTION | J1: CANCER HISTORY DISTRIBUTION
S5: Total customers count | U5: =COUNTA('Health Care'!A2:A2336) -> 2335
S6: Total hospitalisation count | U6: =COUNTA('Hospitalisation Details'!K2:K2344) -> 2343
S7: Total healthcare costs | U7: =SUM('Hospitalisation Details'!P2:P2344) -> 31768896
S8: Average costs and medical metrics | U8: =AVERAGE('Medical Examinations'!B2:B2336) -> 30.972649

Sheet Health Care
A1: Customer ID | B1: First Name | C1: BMI | D1: Heart Issues | E1: Any Transplants | F1: Cancer history | G1: NumberOfMajorSurgeries | H1: smoker | I1: Weight Status | J1: Date of Birth | K1: charges | L1: Hospital tier | M1: City tier | N1: State ID
A2: Id1 | B2: =_xlfn.XLOOKUP(A2,'Customer Names'!E2:E2336,'Customer Names'!H2:H2336) -> Hawks | C2: 47.41 | D2: =_xlfn.XLOOKUP(A2,'Medical Examinations'!J2:J2336,'Medical Examinations'!M2:M2336) -> No | E2: =_xlfn.XLOOKUP(A2,'Medical Examinations'!J2:J2336,'Medical Examinations'!N2:N2336) -> No | F2: =_xlfn.XLOOKUP(A2,'Medical Examinations'!J2:J2336,'Medical Examinations'!O2:O2336) -> No | G2: 0 | H2: =_xlfn.XLOOKUP(A2,'Medical Examinations'!J2:J2336,'Medical Examinations'!Q2:Q2336) -> Yes | I2: =_xlfn.XLOOKUP(A2,'Medical Examinations'!J2:J2336,'Medical Examinations'!S2:S2336) -> Obesity | J2: =_xlfn.XLOOKUP(A2,'Hospitalisation Details'!$K$2:$K$2344,'Hospitalisation Details'!$V$2:$V$2344,0) -> 12-Oct-1968 | K2: =_xlfn.XLOOKUP(A2,'Hospitalisation Details'!$K$2:$K$2344,'Hospitalisation Details'!$P$2:$P$2344,0) -> 63770.43 | L2: =_xlfn.XLOOKUP(A2,'Hospitalisation Details'!$K$2:$K$2344,'Hospitalisation Details'!$Q$2:$Q$2344,0) -> tier - 1 | M2: =_xlfn.XLOOKUP(A2,'Hospitalisation Details'!$K$2:$K$2344,'Hospitalisation Details'!$R$2:$R$2344,0) -> tier - 3 | N2: =_xlfn.XLOOKUP(A2,'Hospitalisation Details'!$K$2:$K$2344,'Hospitalisation Details'!$S$2:$S$2344,0) -> R1013
A3: Id2 | B3: =_xlfn.XLOOKUP(A3,'Customer Names'!E3:E2337,'Customer Names'!H3:H2337) -> Lehner | C3: 30.36 | D3: =_xlfn.XLOOKUP(A3,'Medical Examinations'!J3:J2337,'Medical Examinations'!M3:M2337) -> No | E3: =_xlfn.XLOOKUP(A3,'Medical Examinations'!J3:J2337,'Medical Examinations'!N3:N2337) -> No | F3: =_xlfn.XLOOKUP(A3,'Medical Examinations'!J3:J2337,'Medical Examinations'!O3:O2337) -> No | G3: 0 | H3: =_xlfn.XLOOKUP(A3,'Medical Examinations'!J3:J2337,'Medical Examinations'!Q3:Q2337) -> Yes | I3: =_xlfn.XLOOKUP(A3,'Medical Examinations'!J3:J2337,'Medical Examinations'!S3:S2337) -> Obesity | J3: =_xlfn.XLOOKUP(A3,'Hospitalisation Details'!$K$2:$K$2344,'Hospitalisation Details'!$V$2:$V$2344,0) -> 8-Jun-1977 | K3: =_xlfn.XLOOKUP(A3,'Hospitalisation Details'!$K$2:$K$2344,'Hospitalisation Details'!$P$2:$P$2344,0) -> 62592.87 | L3: =_xlfn.XLOOKUP(A3,'Hospitalisation Details'!$K$2:$K$2344,'Hospitalisation Details'!$Q$2:$Q$2344,0) -> tier - 2 | M3: =_xlfn.XLOOKUP(A3,'Hospitalisation Details'!$K$2:$K$2344,'Hospitalisation Details'!$R$2:$R$2344,0) -> tier - 3 | N3: =_xlfn.XLOOKUP(A3,'Hospitalisation Details'!$K$2:$K$2344,'Hospitalisation Details'!$S$2:$S$2344,0) -> R1013
A4: Id3 | B4: =_xlfn.XLOOKUP(A4,'Customer Names'!E4:E2338,'Customer Names'!H4:H2338) -> Lu | C4: 34.485 | D4: =_xlfn.XLOOKUP(A4,'Medical Examinations'!J4:J2338,'Medical Examinations'!M4:M2338) -> Yes | E4: =_xlfn.XLOOKUP(A4,'Medical Examinations'!J4:J2338,'Medical Examinations'!N4:N2338) -> No | F4: =_xlfn.XLOOKUP(A4,'Medical Examinations'!J4:J2338,'Medical Examinations'!O4:O2338) -> No | G4: 2 | H4: =_xlfn.XLOOKUP(A4,'Medical Examinations'!J4:J2338,'Medical Examinations'!Q4:Q2338) -> Yes | I4: =_xlfn.XLOOKUP(A4,'Medical Examinations'!J4:J2338,'Medical Examinations'!S4:S2338) -> Obesity | J4: =_xlfn.XLOOKUP(A4,'Hospitalisation Details'!$K$2:$K$2344,'Hospitalisation Details'!$V$2:$V$2344,0) -> 11-Sep-1970 | K4: =_xlfn.XLOOKUP(A4,'Hospitalisation Details'!$K$2:$K$2344,'Hospitalisation Details'!$P$2:$P$2344,0) -> 60021.4 | L4: =_xlfn.XLOOKUP(A4,'Hospitalisation Details'!$K$2:$K$2344,'Hospitalisation Details'!$Q$2:$Q$2344,0) -> tier - 1 | M4: =_xlfn.XLOOKUP(A4,'Hospitalisation Details'!$K$2:$K$2344,'Hospitalisation Details'!$R$2:$R$2344,0) -> tier - 1 | N4: =_xlfn.XLOOKUP(A4,'Hospitalisation Details'!$K$2:$K$2344,'Hospitalisation Details'!$S$2:$S$2344,0) -> R1012
A5: Id4 | B5: =_xlfn.XLOOKUP(A5,'Customer Names'!E5:E2339,'Customer Names'!H5:H2339) -> Osborne | C5: 38.095 | D5: =_xlfn.XLOOKUP(A5,'Medical Examinations'!J5:J2339,'Medical Examinations'!M5:M2339) -> No | E5: =_xlfn.XLOOKUP(A5,'Medical Examinations'!J5:J2339,'Medical Examinations'!N5:N2339) -> No | F5: =_xlfn.XLOOKUP(A5,'Medical Examinations'!J5:J2339,'Medical Examinations'!O5:O2339) -> No | G5: 0 | H5: =_xlfn.XLOOKUP(A5,'Medical Examinations'!J5:J2339,'Medical Examinations'!Q5:Q2339) -> Yes | I5: =_xlfn.XLOOKUP(A5,'Medical Examinations'!J5:J2339,'Medical Examinations'!S5:S2339) -> Obesity | J5: =_xlfn.XLOOKUP(A5,'Hospitalisation Details'!$K$2:$K$2344,'Hospitalisation Details'!$V$2:$V$2344,0) -> 6-Jun-1991 | K5: =_xlfn.XLOOKUP(A5,'Hospitalisation Details'!$K$2:$K$2344,'Hospitalisation Details'!$P$2:$P$2344,0) -> 58571.07 | L5: =_xlfn.XLOOKUP(A5,'Hospitalisation Details'!$K$2:$K$2344,'Hospitalisation Details'!$Q$2:$Q$2344,0) -> tier - 1 | M5: =_xlfn.XLOOKUP(A5,'Hospitalisation Details'!$K$2:$K$2344,'Hospitalisation Details'!$R$2:$R$2344,0) -> tier - 3 | N5: =_xlfn.XLOOKUP(A5,'Hospitalisation Details'!$K$2:$K$2344,'Hospitalisation Details'!$S$2:$S$2344,0) -> R1024
A6: Id5 | B6: =_xlfn.XLOOKUP(A6,'Customer Names'!E6:E2340,'Customer Names'!H6:H2340) -> Kadala | C6: 35.53 | D6: =_xlfn.XLOOKUP(A6,'Medical Examinations'!J6:J2340,'Medical Examinations'!M6:M2340) -> No | E6: =_xlfn.XLOOKUP(A6,'Medical Examinations'!J6:J2340,'Medical Examinations'!N6:N2340) -> No | F6: =_xlfn.XLOOKUP(A6,'Medical Examinations'!J6:J2340,'Medical Examinations'!O6:O2340) -> No | G6: 0 | H6: =_xlfn.XLOOKUP(A6,'Medical Examinations'!J6:J2340,'Medical Examinations'!Q6:Q2340) -> Yes | I6: =_xlfn.XLOOKUP(A6,'Medical Examinations'!J6:J2340,'Medical Examinations'!S6:S2340) -> Obesity | J6: =_xlfn.XLOOKUP(A6,'Hospitalisation Details'!$K$2:$K$2344,'Hospitalisation Details'!$V$2:$V$2344,0) -> 19-Jun-1989 | K6: =_xlfn.XLOOKUP(A6,'Hospitalisation Details'!$K$2:$K$2344,'Hospitalisation Details'!$P$2:$P$2344,0) -> 55135.4 | L6: =_xlfn.XLOOKUP(A6,'Hospitalisation Details'!$K$2:$K$2344,'Hospitalisation Details'!$Q$2:$Q$2344,0) -> tier - 1 | M6: =_xlfn.XLOOKUP(A6,'Hospitalisation Details'!$K$2:$K$2344,'Hospitalisation Details'!$R$2:$R$2344,0) -> tier - 2 | N6: =_xlfn.XLOOKUP(A6,'Hospitalisation Details'!$K$2:$K$2344,'Hospitalisation Details'!$S$2:$S$2344,0) -> R1012
A7: Id6 | B7: =_xlfn.XLOOKUP(A7,'Customer Names'!E7:E2341,'Customer Names'!H7:H2341) -> Baker | C7: 32.8 | D7: =_xlfn.XLOOKUP(A7,'Medical Examinations'!J7:J2341,'Medical Examinations'!M7:M2341) -> No | E7: =_xlfn.XLOOKUP(A7,'Medical Examinations'!J7:J2341,'Medical Examinations'!N7:N2341) -> No | F7: =_xlfn.XLOOKUP(A7,'Medical Examinations'!J7:J2341,'Medical Examinations'!O7:O2341) -> No | G7: 0 | H7: =_xlfn.XLOOKUP(A7,'Medical Examinations'!J7:J2341,'Medical Examinations'!Q7:Q2341) -> Yes | I7: =_xlfn.XLOOKUP(A7,'Medical Examinations'!J7:J2341,'Medical Examinations'!S7:S2341) -> Obesity | J7: =_xlfn.XLOOKUP(A7,'Hospitalisation Details'!$K$2:$K$2344,'Hospitalisation Details'!$V$2:$V$2344,0) -> 4-Aug-1962 | K7: =_xlfn.XLOOKUP(A7,'Hospitalisation Details'!$K$2:$K$2344,'Hospitalisation Details'!$P$2:$P$2344,0) -> 52590.83 | L7: =_xlfn.XLOOKUP(A7,'Hospitalisation Details'!$K$2:$K$2344,'Hospitalisation Details'!$Q$2:$Q$2344,0) -> tier - 1 | M7: =_xlfn.XLOOKUP(A7,'Hospitalisation Details'!$K$2:$K$2344,'Hospitalisation Details'!$R$2:$R$2344,0) -> tier - 3 | N7: =_xlfn.XLOOKUP(A7,'Hospitalisation Details'!$K$2:$K$2344,'Hospitalisation Details'!$S$2:$S$2344,0) -> R1011
A8: Id7 | B8: =_xlfn.XLOOKUP(A8,'Customer Names'!E8:E2342,'Customer Names'!H8:H2342) -> Macpherson | C8: 36.4 | D8: =_xlfn.XLOOKUP(A8,'Medical Examinations'!J8:J2342,'Medical Examinations'!M8:M2342) -> No | E8: =_xlfn.XLOOKUP(A8,'Medical Examinations'!J8:J2342,'Medical Examinations'!N8:N2342) -> No | F8: =_xlfn.XLOOKUP(A8,'Medical Examinations'!J8:J2342,'Medical Examinations'!O8:O2342) -> No | G8: 0 | H8: =_xlfn.XLOOKUP(A8,'Medical Examinations'!J8:J2342,'Medical Examinations'!Q8:Q2342) -> Yes | I8: =_xlfn.XLOOKUP(A8,'Medical Examinations'!J8:J2342,'Medical Examinations'!S8:S2342) -> Obesity | J8: =_xlfn.XLOOKUP(A8,'Hospitalisation Details'!$K$2:$K$2344,'Hospitalisation Details'!$V$2:$V$2344,0) -> 27-Oct-1994 | K8: =_xlfn.XLOOKUP(A8,'Hospitalisation Details'!$K$2:$K$2344,'Hospitalisation Details'!$P$2:$P$2344,0) -> 51194.56 | L8: =_xlfn.XLOOKUP(A8,'Hospitalisation Details'!$K$2:$K$2344,'Hospitalisation Details'!$Q$2:$Q$2344,0) -> tier - 1 | M8: =_xlfn.XLOOKUP(A8,'Hospitalisation Details'!$K$2:$K$2344,'Hospitalisation Details'!$R$2:$R$2344,0) -> tier - 3 | N8: =_xlfn.XLOOKUP(A8,'Hospitalisation Details'!$K$2:$K$2344,'Hospitalisation Details'!$S$2:$S$2344,0) -> R1011
A9: Id8 | B9: =_xlfn.XLOOKUP(A9,'Customer Names'!E9:E2343,'Customer Names'!H9:H2343) -> Hallman | C9: 36.96 | D9: =_xlfn.XLOOKUP(A9,'Medical Examinations'!J9:J2343,'Medical Examinations'!M9:M2343) -> No | E9: =_xlfn.XLOOKUP(A9,'Medical Examinations'!J9:J2343,'Medical Examinations'!N9:N2343) -> No | F9: =_xlfn.XLOOKUP(A9,'Medical Examinations'!J9:J2343,'Medical Examinations'!O9:O2343) -> No | G9: 3 | H9: =_xlfn.XLOOKUP(A9,'Medical Examinations'!J9:J2343,'Medical Examinations'!Q9:Q2343) -> Yes | I9: =_xlfn.XLOOKUP(A9,'Medical Examinations'!J9:J2343,'Medical Examinations'!S9:S2343) -> Obesity | J9: =_xlfn.XLOOKUP(A9,'Hospitalisation Details'!$K$2:$K$2344,'Hospitalisation Details'!$V$2:$V$2344,0) -> 27-Jun-1958 | K9: =_xlfn.XLOOKUP(A9,'Hospitalisation Details'!$K$2:$K$2344,'Hospitalisation Details'!$P$2:$P$2344,0) -> 49577.66 | L9: =_xlfn.XLOOKUP(A9,'Hospitalisation Details'!$K$2:$K$2344,'Hospitalisation Details'!$Q$2:$Q$2344,0) -> tier - 2 | M9: =_xlfn.XLOOKUP(A9,'Hospitalisation Details'!$K$2:$K$2344,'Hospitalisation Details'!$R$2:$R$2344,0) -> tier - 2 | N9: =_xlfn.XLOOKUP(A9,'Hospitalisation Details'!$K$2:$K$2344,'Hospitalisation Details'!$S$2:$S$2344,0) -> R1013
A10: Id9 | B10: =_xlfn.XLOOKUP(A10,'Customer Names'!E10:E2344,'Customer Names'!H10:H2344) -> Moran | C10: 41.14 | D10: =_xlfn.XLOOKUP(A10,'Medical Examinations'!J10:J2344,'Medical Examinations'!M10:M2344) -> Yes | E10: =_xlfn.XLOOKUP(A10,'Medical Examinations'!J10:J2344,'Medical Examinations'!N10:N2344) -> No | F10: =_xlfn.XLOOKUP(A10,'Medical Examinations'!J10:J2344,'Medical Examinations'!O10:O2344) -> Yes | G10: 1 | H10: =_xlfn.XLOOKUP(A10,'Medical Examinations'!J10:J2344,'Medical Examinations'!Q10:Q2344) -> Yes | I10: =_xlfn.XLOOKUP(A10,'Medical Examinations'!J10:J2344,'Medical Examinations'!S10:S2344) -> Obesity | J10: =_xlfn.XLOOKUP(A10,'Hospitalisation Details'!$K$2:$K$2344,'Hospitalisation Details'!$V$2:$V$2344,0) -> 4-Sep-1963 | K10: =_xlfn.XLOOKUP(A10,'Hospitalisation Details'!$K$2:$K$2344,'Hospitalisation Details'!$P$2:$P$2344,0) -> 48970.25 | L10: =_xlfn.XLOOKUP(A10,'Hospitalisation Details'!$K$2:$K$2344,'Hospitalisation Details'!$Q$2:$Q$2344,0) -> tier - 1 | M10: =_xlfn.XLOOKUP(A10,'Hospitalisation Details'!$K$2:$K$2344,'Hospitalisation Details'!$R$2:$R$2344,0) -> tier - 2 | N10: =_xlfn.XLOOKUP(A10,'Hospitalisation Details'!$K$2:$K$2344,'Hospitalisation Details'!$S$2:$S$2344,0) -> R1013
A11: Id10 | B11: =_xlfn.XLOOKUP(A11,'Customer Names'!E11:E2345,'Customer Names'!H11:H2345) -> Benner | C11: 38.06 | D11: =_xlfn.XLOOKUP(A11,'Medical Examinations'!J11:J2345,'Medical Examinations'!M11:M2345) -> No | E11: =_xlfn.XLOOKUP(A11,'Medical Examinations'!J11:J2345,'Medical Examinations'!N11:N2345) -> No | F11: =_xlfn.XLOOKUP(A11,'Medical Examinations'!J11:J2345,'Medical Examinations'!O11:O2345) -> No | G11: 0 | H11: =_xlfn.XLOOKUP(A11,'Medical Examinations'!J11:J2345,'Medical Examinations'!Q11:Q2345) -> Yes | I11: =_xlfn.XLOOKUP(A11,'Medical Examinations'!J11:J2345,'Medical Examinations'!S11:S2345) -> Obesity | J11: =_xlfn.XLOOKUP(A11,'Hospitalisation Details'!$K$2:$K$2344,'Hospitalisation Details'!$V$2:$V$2344,0) -> 29-Dec-1978 | K11: =_xlfn.XLOOKUP(A11,'Hospitalisation Details'!$K$2:$K$2344,'Hospitalisation Details'!$P$2:$P$2344,0) -> 48885.14 | L11: =_xlfn.XLOOKUP(A11,'Hospitalisation Details'!$K$2:$K$2344,'Hospitalisation Details'!$Q$2:$Q$2344,0) -> tier - 1 | M11: =_xlfn.XLOOKUP(A11,'Hospitalisation Details'!$K$2:$K$2344,'Hospitalisation Details'!$R$2:$R$2344,0) -> tier - 2 | N11: =_xlfn.XLOOKUP(A11,'Hospitalisation Details'!$K$2:$K$2344,'Hospitalisation Details'!$S$2:$S$2344,0) -> R1013
A12: Id11 | B12: =_xlfn.XLOOKUP(A12,'Customer Names'!E12:E2346,'Customer Names'!H12:H2346) -> Fierro Vargas | C12: 37.7 | D12: =_xlfn.XLOOKUP(A12,'Medical Examinations'!J12:J2346,'Medical Examinations'!M12:M2346) -> Yes | E12: =_xlfn.XLOOKUP(A12,'Medical Examinations'!J12:J2346,'Medical Examinations'!N12:N2346) -> No | F12: =_xlfn.XLOOKUP(A12,'Medical Examinations'!J12:J2346,'Medical Examinations'!O12:O2346) -> No | G12: 2 | H12: =_xlfn.XLOOKUP(A12,'Medical Examinations'!J12:J2346,'Medical Examinations'!Q12:Q2346) -> Yes | I12: =_xlfn.XLOOKUP(A12,'Medical Examinations'!J12:J2346,'Medical Examinations'!S12:S2346) -> Obesity | J12: =_xlfn.XLOOKUP(A12,'Hospitalisation Details'!$K$2:$K$2344,'Hospitalisation Details'!$V$2:$V$2344,0) -> 22-Jul-1959 | K12: =_xlfn.XLOOKUP(A12,'Hospitalisation Details'!$K$2:$K$2344,'Hospitalisation Details'!$P$2:$P$2344,0) -> 48824.45 | L12: =_xlfn.XLOOKUP(A12,'Hospitalisation Details'!$K$2:$K$2344,'Hospitalisation Details'!$Q$2:$Q$2344,0) -> tier - 2 | M12: =_xlfn.XLOOKUP(A12,'Hospitalisation Details'!$K$2:$K$2344,'Hospitalisation Details'!$R$2:$R$2344,0) -> tier - 1 | N12: =_xlfn.XLOOKUP(A12,'Hospitalisation Details'!$K$2:$K$2344,'Hospitalisation Details'!$S$2:$S$2344,0) -> R1011
A13: Id12 | B13: =_xlfn.XLOOKUP(A13,'Customer Names'!E13:E2347,'Customer Names'!H13:H2347) -> Franz | C13: 42.13 | D13: =_xlfn.XLOOKUP(A13,'Medical Examinations'!J13:J2347,'Medical Examinations'!M13:M2347) -> No | E13: =_xlfn.XLOOKUP(A13,'Medical Examinations'!J13:J2347,'Medical Examinations'!N13:N2347) -> No | F13: =_xlfn.XLOOKUP(A13,'Medical Examinations'!J13:J2347,'Medical Examinations'!O13:O2347) -> No | G13: 0 | H13: =_xlfn.XLOOKUP(A13,'Medical Examinations'!J13:J2347,'Medical Examinations'!Q13:Q2347) -> Yes | I13: =_xlfn.XLOOKUP(A13,'Medical Examinations'!J13:J2347,'Medical Examinations'!S13:S2347) -> Obesity | J13: =_xlfn.XLOOKUP(A13,'Hospitalisation Details'!$K$2:$K$2344,'Hospitalisation Details'!$V$2:$V$2344,0) -> 27-Oct-1965 | K13: =_xlfn.XLOOKUP(A13,'Hospitalisation Details'!$K$2:$K$2344,'Hospitalisation Details'!$P$2:$P$2344,0) -> 48675.52 | L13: =_xlfn.XLOOKUP(A13,'Hospitalisation Details'!$K$2:$K$2344,'Hospitalisation Details'!$Q$2:$Q$2344,0) -> tier - 1 | M13: =_xlfn.XLOOKUP(A13,'Hospitalisation Details'!$K$2:$K$2344,'Hospitalisation Details'!$R$2:$R$2344,0) -> tier - 2 | N13: =_xlfn.XLOOKUP(A13,'Hospitalisation Details'!$K$2:$K$2344,'Hospitalisation Details'!$S$2:$S$2344,0) -> R1013
... A2336: Id2335 | B2336: =_xlfn.XLOOKUP(A2336,'Customer Names'!E2336:E4670,'Customer Names'!H2336:H4670) -> German | C2336: 17.58 | D2336: =_xlfn.XLOOKUP(A2336,'Medical Examinations'!J2336:J4670,'Medical Examinations'!M2336:M4670) -> No | E2336: =_xlfn.XLOOKUP(A2336,'Medical Examinations'!J2336:J4670,'Medical Examinations'!N2336:N4670) -> No | F2336: =_xlfn.XLOOKUP(A2336,'Medical Examinations'!J2336:J4670,'Medical Examinations'!O2336:O4670) -> No | G2336: 1 | H2336: =_xlfn.XLOOKUP(A2336,'Medical Examinations'!J2336:J4670,'Medical Examinations'!Q2336:Q4670) -> No | I2336: =_xlfn.XLOOKUP(A2336,'Medical Examinations'!J2336:J4670,'Medical Examinations'!S2336:S4670) -> Under Weight | J2336: =_xlfn.XLOOKUP(A2336,'Hospitalisation Details'!$K$2:$K$2344,'Hospitalisation Details'!$V$2:$V$2344,0) -> 9-Jul-1992 | K2336: =_xlfn.XLOOKUP(A2336,'Hospitalisation Details'!$K$2:$K$2344,'Hospitalisation Details'!$P$2:$P$2344,0) -> 563.84 | L2336: =_xlfn.XLOOKUP(A2336,'Hospitalisation Details'!$K$2:$K$2344,'Hospitalisation Details'!$Q$2:$Q$2344,0) -> tier - 2 | M2336: =_xlfn.XLOOKUP(A2336,'Hospitalisation Details'!$K$2:$K$2344,'Hospitalisation Details'!$R$2:$R$2344,0) -> tier - 3 | N2336: =_xlfn.XLOOKUP(A2336,'Hospitalisation Details'!$K$2:$K$2344,'Hospitalisation Details'!$S$2:$S$2344,0) -> R1013
